<?xml version="1.0" ?>
<robot name="amr" xmlns:xacro="http://www.ros.org/wiki/xacro">

<xacro:include filename="$(find amr_description)/urdf/materials.xacro" />
<xacro:include filename="$(find amr_description)/urdf/amr.trans" />
<xacro:include filename="$(find amr_description)/urdf/amr.gazebo" />
<link name="base_link">
  <inertial>
    <origin xyz="0.0 0.0 0.0" rpy="0 0 0"/>
    <mass value="0.0"/>
    <inertia ixx="0.0" iyy="0.0" izz="0.0" ixy="0.0" iyz="0.0" ixz="0.0"/>
  </inertial>
  <visual>
    <origin xyz="0 0 0" rpy="0 0 0"/>
    <geometry>
      <mesh filename="file://$(find amr_description)/meshes/base_link.stl" scale="0.001 0.001 0.001"/>
    </geometry>
    <material name="silver"/>
  </visual>
  <collision>
    <origin xyz="0 0 0" rpy="0 0 0"/>
    <geometry>
      <mesh filename="file://$(find amr_description)/meshes/base_link.stl" scale="0.001 0.001 0.001"/>
    </geometry>
  </collision>
</link>

<link name="L_wheel_1">
  <inertial>
    <origin xyz="-4.863095991319843e-07 -1.357890951347862e-07 2.1207981681925503e-07" rpy="0 0 0"/>
    <mass value="0.5"/>
    <inertia ixx="0.000573" iyy="0.001077" izz="0.000573" ixy="-0.0" iyz="0.0" ixz="0.0"/>
  </inertial>
  <visual>
    <origin xyz="0.054114 -0.17519 -0.067088" rpy="0 0 0"/>
    <geometry>
      <mesh filename="file://$(find amr_description)/meshes/L_wheel_1.stl" scale="0.001 0.001 0.001"/>
    </geometry>
    <material name="silver"/>
  </visual>
  <collision>
    <origin xyz="0.054114 -0.17519 -0.067088" rpy="0 0 0"/>
    <geometry>
      <mesh filename="file://$(find amr_description)/meshes/L_wheel_1.stl" scale="0.001 0.001 0.001"/>
    </geometry>
  </collision>
</link>

<link name="R_wheel_1">
  <inertial>
    <origin xyz="-4.863095917836957e-07 -1.357890967446096e-07 2.1207981767967787e-07" rpy="0 0 0"/>
    <mass value="0.5"/>
    <inertia ixx="0.000573" iyy="0.001077" izz="0.000573" ixy="-0.0" iyz="-0.0" ixz="-0.0"/>
  </inertial>
  <visual>
    <origin xyz="0.054114 0.41981 -0.067088" rpy="0 0 0"/>
    <geometry>
      <mesh filename="file://$(find amr_description)/meshes/R_wheel_1.stl" scale="0.001 0.001 0.001"/>
    </geometry>
    <material name="silver"/>
  </visual>
  <collision>
    <origin xyz="0.054114 0.41981 -0.067088" rpy="0 0 0"/>
    <geometry>
      <mesh filename="file://$(find amr_description)/meshes/R_wheel_1.stl" scale="0.001 0.001 0.001"/>
    </geometry>
  </collision>
</link>

<link name="mr_robot/base_link/gpu_lidar">
  <inertial>
    <origin xyz="0.21693818631555356 -0.2885381579659291 0.025435818960008738" rpy="0 0 0"/>
    <mass value="0.0000000000000000000000000000000000000000000000000000000000000000000000000000000000000000000000000000000000001"/>
    <inertia ixx="0.000187" iyy="0.000238" izz="0.000313" ixy="-3e-06" iyz="-4e-06" ixz="-2.1e-05"/>
  </inertial>
  <visual>
    <origin xyz="0.021443 -0.164774 -0.326707" rpy="0 0 0"/>
    <geometry>
      <mesh filename="file://$(find amr_description)/meshes/rplidar-a2m4-r1_v1_1.stl" scale="0.001 0.001 0.001"/>
    </geometry>
    <material name="silver"/>
  </visual>
  <collision>
    <origin xyz="0.021443 -0.164774 -0.326707" rpy="0 0 0"/>
    <geometry>
      <mesh filename="file://$(find amr_description)/meshes/rplidar-a2m4-r1_v1_1.stl" scale="0.001 0.001 0.001"/>
    </geometry>
  </collision>
</link>

<link name="sensor_rod_1">
  <inertial>
    <origin xyz="-4.863096013663082e-07 0.021999864240703368 2.279670597200245" rpy="0 0 0"/>
    <mass value="0.0"/>
    <inertia ixx="20.793443" iyy="20.793445" izz="0.007056" ixy="0.0" iyz="0.0" ixz="0.0"/>
  </inertial>
  <visual>
    <origin xyz="0.033114 0.12231 -0.435588" rpy="0 0 0"/>
    <geometry>
      <mesh filename="file://$(find amr_description)/meshes/sensor_rod_1.stl" scale="0.001 0.001 0.0007"/>
    </geometry>
    <material name="silver"/>
  </visual>
  <collision>
    <origin xyz="0.033114 0.12231 -0.435588" rpy="0 0 0"/>
    <geometry>
      <mesh filename="file://$(find amr_description)/meshes/sensor_rod_1.stl" scale="0.001 0.001 0.0007"/>
    </geometry>
  </collision>
</link>

<joint name="L_wheel_joint" type="continuous">
  <origin xyz="-0.054114 0.17519 0.067088" rpy="0 0 0"/>
  <parent link="base_link"/>
  <child link="L_wheel_1"/>
  <axis xyz="0.0 1.0 0.0"/>
</joint>

<joint name="R_wheel_joint" type="continuous">
  <origin xyz="-0.054114 -0.41981 0.067088" rpy="0 0 0"/>
  <parent link="base_link"/>
  <child link="R_wheel_1"/>
  <axis xyz="0.0 1.0 0.0"/>
</joint>

<joint name="Rigid 12" type="fixed">
  <origin xyz="-0.021443 0.164774 0.326707" rpy="0 0 0"/>
  <parent link="base_link"/>
  <child link="mr_robot/base_link/gpu_lidar"/>
</joint>

<joint name="Rigid 15" type="fixed">
  <origin xyz="-0.033114 -0.12231 0.435588" rpy="0 0 0"/>
  <parent link="base_link"/>
  <child link="sensor_rod_1"/>
</joint>

</robot>
